<?xml version="1.0"?>
<robot name="URDF_0605_L">

  <link name="base_link" />

    <link name="HOUSING-L">
      <visual>
        <origin xyz="0 0 0" rpy="0 0 0" />
        <geometry>
          <mesh filename="meshes/visual/HOUSING-L.STL" />
        </geometry>
        <material name="black_material">
          <color rgba="0.14000000 0.15000000 0.16000000 1.00000000"/>
        </material>
      </visual>
      <inertial>
        <origin xyz="-0.0000111 -0.085871 -0.0003395" rpy="0 0 0" />
        <mass value="0.5561357" />
        <inertia ixx="0.0010606" ixy="0.0000006" ixz="0" iyy="0.0004326" iyz="-0.0000165" izz="0.0012833" />
      </inertial>
    </link>

    <link name="WRIST-PALM-L">
      <visual>
        <origin xyz="0 0 0" rpy="0 0 0" />
        <geometry>
          <mesh filename="meshes/visual/WRIST-PALM-L.STL" />
        </geometry>
        <material name="dark_gray_material">
          <color rgba="0.42000000 0.44000000 0.46000000 1.00000000"/>
        </material>
      </visual>
      <inertial>
        <origin xyz="0.0000001 0.0098109 -0.0002551" rpy="0 0 0" />
        <mass value="0.0356302" />
        <inertia ixx="0.0000063" ixy="0" ixz="0" iyy="0.0000075" iyz="0" izz="0.0000061" />
      </inertial>
    </link>

    <link name="PALM-L">
      <visual>
        <origin xyz="0 0 0" rpy="0 0 0" />
        <geometry>
          <mesh filename="meshes/visual/PALM-L.STL" />
        </geometry>
        <material name="dark_gray_material">
          <color rgba="0.42000000 0.44000000 0.46000000 1.00000000"/>
        </material>
      </visual>
      <inertial>
        <origin xyz="0.0122781 0.038595 0.0020082" rpy="0 0 0" />
        <mass value="0.1364434" />
        <inertia ixx="0.0000619" ixy="-0.0000115" ixz="-0.0000014" iyy="0.0000437" iyz="-0.0000038" izz="0.0000993" />
      </inertial>
    </link>

    <link name="F1-L-MCP2">
      <visual>
        <origin xyz="0 0 0" rpy="0 0 0" />
        <geometry>
          <mesh filename="meshes/visual/F1-L-MCP2.STL" />
        </geometry>
        <material name="dark_gray_material">
          <color rgba="0.42000000 0.44000000 0.46000000 1.00000000"/>
        </material>
      </visual>
      <inertial>
        <origin xyz="-0.0051493 0.0066497 0.003465" rpy="0 0 0" />
        <mass value="0.0034154" />
        <inertia ixx="0.0000001" ixy="0" ixz="0" iyy="0.0000001" iyz="0" izz="0.0000002" />
      </inertial>
    </link>

    <link name="F1-L-MCP1">
      <visual>
        <origin xyz="0 0 0" rpy="0 0 0" />
        <geometry>
          <mesh filename="meshes/visual/F1-L-MCP1.STL" />
        </geometry>
        <material name="dark_gray_material">
          <color rgba="0.42000000 0.44000000 0.46000000 1.00000000"/>
        </material>
      </visual>
      <inertial>
        <origin xyz="0.0062613 0.0157265 -0.0117765" rpy="0 0 0" />
        <mass value="0.0229565" />
        <inertia ixx="0.0000024" ixy="0" ixz="0" iyy="0.000002" iyz="0.0000008" izz="0.0000021" />
      </inertial>
    </link>

    <link name="F1-L-PIP">
      <visual>
        <origin xyz="0 0 0" rpy="0 0 0" />
        <geometry>
          <mesh filename="meshes/visual/F1-L-PIP.STL" />
        </geometry>
        <material name="dark_gray_material">
          <color rgba="0.42000000 0.44000000 0.46000000 1.00000000"/>
        </material>
      </visual>
      <!-- ═══════════════════════════════════════════ -->
      <!--  PIP marker (blue sphere, radius 0.004)   -->
      <!-- ═══════════════════════════════════════════ -->
      <visual name="F1-L-PIP-marker">
        <origin xyz="0.004 -0.001 0.001" rpy="0 0 0" />
        <geometry>
          <sphere radius="0.004" />
        </geometry>
        <material name="pip_marker_blue">
          <color rgba="0.00000000 0.35000000 1.00000000 1.00000000"/>
        </material>
      </visual>
      <!-- ═══════════════════════════════════════════ -->
      <inertial>
        <origin xyz="0.0041998 0.0108245 -0.0102906" rpy="0 0 0" />
        <mass value="0.010446" />
        <inertia ixx="0.0000007" ixy="0" ixz="0" iyy="0.0000006" iyz="0.0000002" izz="0.0000007" />
      </inertial>
    </link>

    <link name="F1-L-DIP">
      <visual>
        <origin xyz="0 0 0" rpy="0 0 0" />
        <geometry>
          <mesh filename="meshes/visual/F1-L-DIP.STL" />
        </geometry>
        <material name="dark_gray_material">
          <color rgba="0.42000000 0.44000000 0.46000000 1.00000000"/>
        </material>
      </visual>
      <!-- ═══════════════════════════════════════════ -->
      <!--  TIP marker (red sphere, radius 0.004)    -->
      <!-- ═══════════════════════════════════════════ -->
      <visual name="F1-L-TIP-marker">
        <origin xyz="0.005 0.018 -0.018" rpy="0 0 0" />
        <geometry>
          <sphere radius="0.004" />
        </geometry>
        <material name="tip_marker_red">
          <color rgba="1.00000000 0.05000000 0.05000000 1.00000000"/>
        </material>
      </visual>
      <!-- ═══════════════════════════════════════════ -->
      <inertial>
        <origin xyz="0.0041998 0.0088881 -0.0097563" rpy="0 0 0" />
        <mass value="0.0076488" />
        <inertia ixx="0.0000004" ixy="0" ixz="0" iyy="0.0000004" iyz="0.0000001" izz="0.0000004" />
      </inertial>
    </link>

    <link name="F2-L-MCP2">
      <visual>
        <origin xyz="0 0 0" rpy="0 0 0" />
        <geometry>
          <mesh filename="meshes/visual/F2-L-MCP2.STL" />
        </geometry>
        <material name="dark_gray_material">
          <color rgba="0.42000000 0.44000000 0.46000000 1.00000000"/>
        </material>
      </visual>
      <inertial>
        <origin xyz="0 0.0032303 0.0002549" rpy="0 0 0" />
        <mass value="0.0025219" />
        <inertia ixx="0.0000002" ixy="0" ixz="0" iyy="0.0000001" iyz="0" izz="0.0000001" />
      </inertial>
    </link>

    <link name="F2-L-MCP1">
      <visual>
        <origin xyz="0 0 0" rpy="0 0 0" />
        <geometry>
          <mesh filename="meshes/visual/F2-L-MCP1.STL" />
        </geometry>
        <material name="dark_gray_material">
          <color rgba="0.42000000 0.44000000 0.46000000 1.00000000"/>
        </material>
      </visual>
      <inertial>
        <origin xyz="0.0000009 0.0177238 0.0007805" rpy="0 0 0" />
        <mass value="0.0145312" />
        <inertia ixx="0.0000022" ixy="0" ixz="0" iyy="0.0000005" iyz="-0.0000001" izz="0.0000024" />
      </inertial>
    </link>

    <link name="F2-L-PIP">
      <visual>
        <origin xyz="0 0 0" rpy="0 0 0" />
        <geometry>
          <mesh filename="meshes/visual/F2-L-PIP.STL" />
        </geometry>
        <material name="dark_gray_material">
          <color rgba="0.42000000 0.44000000 0.46000000 1.00000000"/>
        </material>
      </visual>
      <!-- ═══════════════════════════════════════════ -->
      <!--  PIP marker (blue sphere, radius 0.004)   -->
      <!-- ═══════════════════════════════════════════ -->
      <visual name="F2-L-PIP-marker">
        <origin xyz="0 0 0" rpy="0 0 0" />
        <geometry>
          <sphere radius="0.004" />
        </geometry>
        <material name="pip_marker_blue">
          <color rgba="0.00000000 0.35000000 1.00000000 1.00000000"/>
        </material>
      </visual>
      <!-- ═══════════════════════════════════════════ -->
      <inertial>
        <origin xyz="-0.0000006 0.0111296 -0.000548" rpy="0 0 0" />
        <mass value="0.0050184" />
        <inertia ixx="0.0000003" ixy="0" ixz="0" iyy="0.0000001" iyz="0" izz="0.0000003" />
      </inertial>
    </link>

    <link name="F2-L-DIP">
      <visual>
        <origin xyz="0 0 0" rpy="0 0 0" />
        <geometry>
          <mesh filename="meshes/visual/F2-L-DIP.STL" />
        </geometry>
        <material name="dark_gray_material">
          <color rgba="0.42000000 0.44000000 0.46000000 1.00000000"/>
        </material>
      </visual>
      <!-- ═══════════════════════════════════════════ -->
      <!--  TIP marker (red sphere, radius 0.004)    -->
      <!-- ═══════════════════════════════════════════ -->
      <visual name="F2-L-TIP-marker">
        <origin xyz="0 0.018 0" rpy="0 0 0" />
        <geometry>
          <sphere radius="0.004" />
        </geometry>
        <material name="tip_marker_red">
          <color rgba="1.00000000 0.05000000 0.05000000 1.00000000"/>
        </material>
      </visual>
      <!-- ═══════════════════════════════════════════ -->
      <inertial>
        <origin xyz="-0.0000009 0.0103728 -0.0010699" rpy="0 0 0" />
        <mass value="0.0036931" />
        <inertia ixx="0.0000001" ixy="0" ixz="0" iyy="0.0000001" iyz="0" izz="0.0000002" />
      </inertial>
    </link>

    <link name="F3-L-MCP2">
      <visual>
        <origin xyz="0 0 0" rpy="0 0 0" />
        <geometry>
          <mesh filename="meshes/visual/F3-L-MCP2.STL" />
        </geometry>
        <material name="dark_gray_material">
          <color rgba="0.42000000 0.44000000 0.46000000 1.00000000"/>
        </material>
      </visual>
      <inertial>
        <origin xyz="-0.0000008 0.0032575 0.0002549" rpy="0 0 0" />
        <mass value="0.0025219" />
        <inertia ixx="0.0000002" ixy="0" ixz="0" iyy="0.0000001" iyz="0" izz="0.0000001" />
      </inertial>
    </link>

    <link name="F3-L-MCP1">
      <visual>
        <origin xyz="0 0 0" rpy="0 0 0" />
        <geometry>
          <mesh filename="meshes/visual/F3-L-MCP1.STL" />
        </geometry>
        <material name="dark_gray_material">
          <color rgba="0.42000000 0.44000000 0.46000000 1.00000000"/>
        </material>
      </visual>
      <inertial>
        <origin xyz="0.0000232 0.017751 0.0007805" rpy="0 0 0" />
        <mass value="0.0145312" />
        <inertia ixx="0.0000022" ixy="0" ixz="0" iyy="0.0000005" iyz="-0.0000001" izz="0.0000024" />
      </inertial>
    </link>

    <link name="F3-L-PIP">
      <visual>
        <origin xyz="0 0 0" rpy="0 0 0" />
        <geometry>
          <mesh filename="meshes/visual/F3-L-PIP.STL" />
        </geometry>
        <material name="dark_gray_material">
          <color rgba="0.42000000 0.44000000 0.46000000 1.00000000"/>
        </material>
      </visual>
      <!-- ═══════════════════════════════════════════ -->
      <!--  PIP marker (blue sphere, radius 0.004)   -->
      <!-- ═══════════════════════════════════════════ -->
      <visual name="F3-L-PIP-marker">
        <origin xyz="0 0 0" rpy="0 0 0" />
        <geometry>
          <sphere radius="0.004" />
        </geometry>
        <material name="pip_marker_blue">
          <color rgba="0.00000000 0.35000000 1.00000000 1.00000000"/>
        </material>
      </visual>
      <!-- ═══════════════════════════════════════════ -->
      <inertial>
        <origin xyz="-0.0000512 0.0111568 -0.000548" rpy="0 0 0" />
        <mass value="0.0050184" />
        <inertia ixx="0.0000003" ixy="0" ixz="0" iyy="0.0000001" iyz="0" izz="0.0000003" />
      </inertial>
    </link>

    <link name="F3-L-DIP">
      <visual>
        <origin xyz="0 0 0" rpy="0 0 0" />
        <geometry>
          <mesh filename="meshes/visual/F3-L-DIP.STL" />
        </geometry>
        <material name="dark_gray_material">
          <color rgba="0.42000000 0.44000000 0.46000000 1.00000000"/>
        </material>
      </visual>
      <!-- ═══════════════════════════════════════════ -->
      <!--  TIP marker (red sphere, radius 0.004)    -->
      <!-- ═══════════════════════════════════════════ -->
      <visual name="F3-L-TIP-marker">
        <origin xyz="0 0.018 0" rpy="0 0 0" />
        <geometry>
          <sphere radius="0.004" />
        </geometry>
        <material name="tip_marker_red">
          <color rgba="1.00000000 0.05000000 0.05000000 1.00000000"/>
        </material>
      </visual>
      <!-- ═══════════════════════════════════════════ -->
      <inertial>
        <origin xyz="-0.0000688 0.0104 -0.001145" rpy="0 0 0" />
        <mass value="0.0036931" />
        <inertia ixx="0.0000001" ixy="0" ixz="0" iyy="0.0000001" iyz="0" izz="0.0000002" />
      </inertial>
    </link>

    <link name="F4-L-MCP2">
      <visual>
        <origin xyz="0 0 0" rpy="0 0 0" />
        <geometry>
          <mesh filename="meshes/visual/F4-L-MCP2.STL" />
        </geometry>
        <material name="dark_gray_material">
          <color rgba="0.42000000 0.44000000 0.46000000 1.00000000"/>
        </material>
      </visual>
      <inertial>
        <origin xyz="0 0.0032303 0.0002549" rpy="0 0 0" />
        <mass value="0.0025219" />
        <inertia ixx="0.0000002" ixy="0" ixz="0" iyy="0.0000001" iyz="0" izz="0.0000001" />
      </inertial>
    </link>

    <link name="F4-L-MCP1">
      <visual>
        <origin xyz="0 0 0" rpy="0 0 0" />
        <geometry>
          <mesh filename="meshes/visual/F4-L-MCP1.STL" />
        </geometry>
        <material name="dark_gray_material">
          <color rgba="0.42000000 0.44000000 0.46000000 1.00000000"/>
        </material>
      </visual>
      <inertial>
        <origin xyz="0.0000009 0.0177238 0.0007805" rpy="0 0 0" />
        <mass value="0.0145312" />
        <inertia ixx="0.0000022" ixy="0" ixz="0" iyy="0.0000005" iyz="-0.0000001" izz="0.0000024" />
      </inertial>
    </link>

    <link name="F4-L-PIP">
      <visual>
        <origin xyz="0 0 0" rpy="0 0 0" />
        <geometry>
          <mesh filename="meshes/visual/F4-L-PIP.STL" />
        </geometry>
        <material name="dark_gray_material">
          <color rgba="0.42000000 0.44000000 0.46000000 1.00000000"/>
        </material>
      </visual>
      <!-- ═══════════════════════════════════════════ -->
      <!--  PIP marker (blue sphere, radius 0.004)   -->
      <!-- ═══════════════════════════════════════════ -->
      <visual name="F4-L-PIP-marker">
        <origin xyz="0 0 0" rpy="0 0 0" />
        <geometry>
          <sphere radius="0.004" />
        </geometry>
        <material name="pip_marker_blue">
          <color rgba="0.00000000 0.35000000 1.00000000 1.00000000"/>
        </material>
      </visual>
      <!-- ═══════════════════════════════════════════ -->
      <inertial>
        <origin xyz="-0.0000006 0.0111296 -0.000548" rpy="0 0 0" />
        <mass value="0.0050184" />
        <inertia ixx="0.0000003" ixy="0" ixz="0" iyy="0.0000001" iyz="0" izz="0.0000003" />
      </inertial>
    </link>

    <link name="F4-L-DIP">
      <visual>
        <origin xyz="0 0 0" rpy="0 0 0" />
        <geometry>
          <mesh filename="meshes/visual/F4-L-DIP.STL" />
        </geometry>
        <material name="dark_gray_material">
          <color rgba="0.42000000 0.44000000 0.46000000 1.00000000"/>
        </material>
      </visual>
      <!-- ═══════════════════════════════════════════ -->
      <!--  TIP marker (red sphere, radius 0.004)    -->
      <!-- ═══════════════════════════════════════════ -->
      <visual name="F4-L-TIP-marker">
        <origin xyz="0 0.018 0" rpy="0 0 0" />
        <geometry>
          <sphere radius="0.004" />
        </geometry>
        <material name="tip_marker_red">
          <color rgba="1.00000000 0.05000000 0.05000000 1.00000000"/>
        </material>
      </visual>
      <!-- ═══════════════════════════════════════════ -->
      <inertial>
        <origin xyz="0.0000543 0.0105111 -0.0011579" rpy="0 0 0" />
        <mass value="0.0036931" />
        <inertia ixx="0.0000001" ixy="0" ixz="0" iyy="0.0000001" iyz="0" izz="0.0000002" />
      </inertial>
    </link>

    <link name="F5-L-MCP2">
      <visual>
        <origin xyz="0 0 0" rpy="0 0 0" />
        <geometry>
          <mesh filename="meshes/visual/F5-L-MCP2.STL" />
        </geometry>
        <material name="dark_gray_material">
          <color rgba="0.42000000 0.44000000 0.46000000 1.00000000"/>
        </material>
      </visual>
      <inertial>
        <origin xyz="0 0.0032303 0.0002549" rpy="0 0 0" />
        <mass value="0.0025219" />
        <inertia ixx="0.0000002" ixy="0" ixz="0" iyy="0.0000001" iyz="0" izz="0.0000001" />
      </inertial>
    </link>

    <link name="F5-L-MCP1">
      <visual>
        <origin xyz="0 0 0" rpy="0 0 0" />
        <geometry>
          <mesh filename="meshes/visual/F5-L-MCP1.STL" />
        </geometry>
        <material name="dark_gray_material">
          <color rgba="0.42000000 0.44000000 0.46000000 1.00000000"/>
        </material>
      </visual>
      <inertial>
        <origin xyz="0.0000009 0.0177238 0.0007805" rpy="0 0 0" />
        <mass value="0.0145312" />
        <inertia ixx="0.0000022" ixy="0" ixz="0" iyy="0.0000005" iyz="-0.0000001" izz="0.0000024" />
      </inertial>
    </link>

    <link name="F5-L-PIP">
      <visual>
        <origin xyz="0 0 0" rpy="0 0 0" />
        <geometry>
          <mesh filename="meshes/visual/F5-L-PIP.STL" />
        </geometry>
        <material name="dark_gray_material">
          <color rgba="0.42000000 0.44000000 0.46000000 1.00000000"/>
        </material>
      </visual>
      <!-- ═══════════════════════════════════════════ -->
      <!--  PIP marker (blue sphere, radius 0.004)   -->
      <!-- ═══════════════════════════════════════════ -->
      <visual name="F5-L-PIP-marker">
        <origin xyz="0 0 0" rpy="0 0 0" />
        <geometry>
          <sphere radius="0.004" />
        </geometry>
        <material name="pip_marker_blue">
          <color rgba="0.00000000 0.35000000 1.00000000 1.00000000"/>
        </material>
      </visual>
      <!-- ═══════════════════════════════════════════ -->
      <inertial>
        <origin xyz="-0.0000006 0.0111296 -0.000548" rpy="0 0 0" />
        <mass value="0.0050184" />
        <inertia ixx="0.0000003" ixy="0" ixz="0" iyy="0.0000001" iyz="0" izz="0.0000003" />
      </inertial>
    </link>

    <link name="F5-L-DIP">
      <visual>
        <origin xyz="0 0 0" rpy="0 0 0" />
        <geometry>
          <mesh filename="meshes/visual/F5-L-DIP.STL" />
        </geometry>
        <material name="dark_gray_material">
          <color rgba="0.42000000 0.44000000 0.46000000 1.00000000"/>
        </material>
      </visual>
      <!-- ═══════════════════════════════════════════ -->
      <!--  TIP marker (red sphere, radius 0.004)    -->
      <!-- ═══════════════════════════════════════════ -->
      <visual name="F5-L-TIP-marker">
        <origin xyz="0 0.018 0" rpy="0 0 0" />
        <geometry>
          <sphere radius="0.004" />
        </geometry>
        <material name="tip_marker_red">
          <color rgba="1.00000000 0.05000000 0.05000000 1.00000000"/>
        </material>
      </visual>
      <!-- ═══════════════════════════════════════════ -->
      <inertial>
        <origin xyz="0.0000014 0.0103743 -0.0010705" rpy="0 0 0" />
        <mass value="0.0036931" />
        <inertia ixx="0.0000001" ixy="0" ixz="0" iyy="0.0000001" iyz="0" izz="0.0000002" />
      </inertial>
    </link>

  <joint name="base_link_to_HOUSING-L" type="fixed">
    <parent link="base_link" />
    <child link="HOUSING-L" />
    <origin xyz="0 0 0" rpy="1.57079632679 0 3.14159265359" />
  </joint>

  <joint name="WRIST-PALM-L" type="revolute">
    <parent link="HOUSING-L" />
    <child link="WRIST-PALM-L" />
    <origin xyz="0 0 0" rpy="0 0 0" />
    <axis xyz="0 0 1" />
    <limit lower="-0.6981" upper="0.6981" effort="12.0" velocity="2.0" />
    <dynamics damping="0.3000" friction="0.2400" />
  </joint>

  <joint name="PALM-L" type="revolute">
    <parent link="WRIST-PALM-L" />
    <child link="PALM-L" />
    <origin xyz="0.016904 0.03005 -0.0003425" rpy="3.1416 0 3.1416" />
    <axis xyz="-1 0 0" />
    <limit lower="-1.3963" upper="1.0472" effort="10.0" velocity="2.5" />
    <dynamics damping="0.2000" friction="0.2000" />
  </joint>

  <joint name="F1-L-MCP2" type="revolute">
    <parent link="PALM-L" />
    <child link="F1-L-MCP2" />
    <origin xyz="0.039199 0.019548 -0.0035" rpy="3.1416 0 3.1416" />
    <axis xyz="0.76604 0.64279 0" />
    <limit lower="-0.35" upper="0.61" effort="6.5" velocity="2.82" />
    <dynamics damping="0.1152" friction="0.1300" />
  </joint>

  <joint name="F1-L-MCP1" type="revolute">
    <parent link="F1-L-MCP2" />
    <child link="F1-L-MCP1" />
    <origin xyz="-0.0049195 0.0066407 0.010162" rpy="2.3078 1.1797 2.2689" />
    <axis xyz="1 0 0" />
    <limit lower="-0.52" upper="0.785" effort="6.0" velocity="3.84" />
    <dynamics damping="0.0781" friction="0.1200" />
  </joint>

  <joint name="F1-L-PIP" type="revolute">
    <parent link="F1-L-MCP1" />
    <child link="F1-L-PIP" />
    <origin xyz="0.00205 0.030797 -0.027817" rpy="0 0 0" />
    <axis xyz="1 0 0" />
    <limit lower="-0.35" upper="1.31" effort="3.5" velocity="4.88" />
    <dynamics damping="0.0359" friction="0.0700" />
  </joint>

  <joint name="F1-L-DIP" type="revolute">
    <parent link="F1-L-PIP" />
    <child link="F1-L-DIP" />
    <origin xyz="0 0.022214 -0.020162" rpy="0 0 0" />
    <axis xyz="1 0 0" />
    <limit lower="-0.35" upper="1.31" effort="1.7" velocity="4.88" />
    <dynamics damping="0.0174" friction="0.0340" />
  </joint>

  <joint name="F2-L-MCP2" type="revolute">
    <parent link="PALM-L" />
    <child link="F2-L-MCP2" />
    <origin xyz="0.04512 0.078019 0.00395" rpy="3.1416 0 2.8798" />
    <axis xyz="0 0 1" />
    <limit lower="-0.61" upper="0.61" effort="6.0" velocity="3.59" />
    <dynamics damping="0.0836" friction="0.1200" />
  </joint>

  <joint name="F2-L-MCP1" type="revolute">
    <parent link="F2-L-MCP2" />
    <child link="F2-L-MCP1" />
    <origin xyz="0 0.01 0.00075" rpy="3.1416 0 3.1416" />
    <axis xyz="-1 0 0" />
    <limit lower="-0.52" upper="1.57" effort="5.5" velocity="6.15" />
    <dynamics damping="0.0447" friction="0.1100" />
  </joint>

  <joint name="F2-L-PIP" type="revolute">
    <parent link="F2-L-MCP1" />
    <child link="F2-L-PIP" />
    <origin xyz="0 0.043109 0.0016488" rpy="3.1416 0 3.1416" />
    <axis xyz="1 0 0" />
    <limit lower="0" upper="1.92" effort="3.0" velocity="5.65" />
    <dynamics damping="0.0265" friction="0.0600" />
  </joint>

  <joint name="F2-L-DIP" type="revolute">
    <parent link="F2-L-PIP" />
    <child link="F2-L-DIP" />
    <origin xyz="0 0.023 0" rpy="0 0 0" />
    <axis xyz="1 0 0" />
    <limit lower="0" upper="1.22" effort="1.5" velocity="3.59" />
    <dynamics damping="0.0209" friction="0.0300" />
  </joint>

  <joint name="F3-L-MCP2" type="revolute">
    <parent link="PALM-L" />
    <child link="F3-L-MCP2" />
    <origin xyz="0.025553 0.083234 0.00395" rpy="3.1416 0 3.1416" />
    <axis xyz="0 0 1" />
    <limit lower="-0.61" upper="0.61" effort="6.0" velocity="3.59" />
    <dynamics damping="0.0836" friction="0.1200" />
  </joint>

  <joint name="F3-L-MCP1" type="revolute">
    <parent link="F3-L-MCP2" />
    <child link="F3-L-MCP1" />
    <origin xyz="0 0.01 0.00075" rpy="3.1415927 0 3.1408173" />
    <axis xyz="-1 0 0" />
    <limit lower="-0.52" upper="1.57" effort="5.5" velocity="6.15" />
    <dynamics damping="0.0447" friction="0.1100" />
  </joint>

  <joint name="F3-L-PIP" type="revolute">
    <parent link="F3-L-MCP1" />
    <child link="F3-L-PIP" />
    <origin xyz="0 0.043109 0.0016488" rpy="3.1416 0 -3.1416" />
    <axis xyz="1 0 0" />
    <limit lower="0" upper="1.92" effort="3.0" velocity="5.65" />
    <dynamics damping="0.0265" friction="0.0600" />
  </joint>

  <joint name="F3-L-DIP" type="revolute">
    <parent link="F3-L-PIP" />
    <child link="F3-L-DIP" />
    <origin xyz="0 0.023 0" rpy="0 0 0" />
    <axis xyz="1 0 0" />
    <limit lower="0" upper="1.22" effort="1.5" velocity="3.59" />
    <dynamics damping="0.0209" friction="0.0300" />
  </joint>

  <joint name="F4-L-MCP2" type="revolute">
    <parent link="PALM-L" />
    <child link="F4-L-MCP2" />
    <origin xyz="0.0059875 0.078019 0.00395" rpy="3.1416 0 3.4034" />
    <axis xyz="0 0 1" />
    <limit lower="-0.61" upper="0.61" effort="6.0" velocity="3.59" />
    <dynamics damping="0.0836" friction="0.1200" />
  </joint>

  <joint name="F4-L-MCP1" type="revolute">
    <parent link="F4-L-MCP2" />
    <child link="F4-L-MCP1" />
    <origin xyz="0 0.01 0.00075" rpy="3.1415927 0 3.1415927" />
    <axis xyz="-1 0 0" />
    <limit lower="-0.52" upper="1.57" effort="5.5" velocity="6.15" />
    <dynamics damping="0.0447" friction="0.1100" />
  </joint>

  <joint name="F4-L-PIP" type="revolute">
    <parent link="F4-L-MCP1" />
    <child link="F4-L-PIP" />
    <origin xyz="0 0.043109 0.0016488" rpy="3.1416 0 3.1416" />
    <axis xyz="1 0 0" />
    <limit lower="0" upper="1.92" effort="3.0" velocity="5.65" />
    <dynamics damping="0.0265" friction="0.0600" />
  </joint>

  <joint name="F4-L-DIP" type="revolute">
    <parent link="F4-L-PIP" />
    <child link="F4-L-DIP" />
    <origin xyz="-0.0000552 0.022862 0.0000129" rpy="0 0 0" />
    <axis xyz="1 0 0" />
    <limit lower="0" upper="1.22" effort="1.5" velocity="3.59" />
    <dynamics damping="0.0209" friction="0.0300" />
  </joint>

  <joint name="F5-L-MCP2" type="revolute">
    <parent link="PALM-L" />
    <child link="F5-L-MCP2" />
    <origin xyz="-0.01361 0.063366 0.00395" rpy="3.1416 0 3.7347" />
    <axis xyz="0 0 1" />
    <limit lower="-0.61" upper="0.61" effort="6.0" velocity="3.59" />
    <dynamics damping="0.0836" friction="0.1200" />
  </joint>

  <joint name="F5-L-MCP1" type="revolute">
    <parent link="F5-L-MCP2" />
    <child link="F5-L-MCP1" />
    <origin xyz="0 0.01 0.00075" rpy="3.1415927 0 3.1415927" />
    <axis xyz="-1 0 0" />
    <limit lower="-0.52" upper="1.57" effort="5.5" velocity="6.15" />
    <dynamics damping="0.0447" friction="0.1100" />
  </joint>

  <joint name="F5-L-PIP" type="revolute">
    <parent link="F5-L-MCP1" />
    <child link="F5-L-PIP" />
    <origin xyz="0 0.043109 0.0016488" rpy="3.1416 0 3.1416" />
    <axis xyz="1 0 0" />
    <limit lower="0" upper="1.92" effort="3.0" velocity="5.65" />
    <dynamics damping="0.0265" friction="0.0600" />
  </joint>

  <joint name="F5-L-DIP" type="revolute">
    <parent link="F5-L-PIP" />
    <child link="F5-L-DIP" />
    <origin xyz="0 0.022994 0" rpy="0 0 0" />
    <axis xyz="1 0 0" />
    <limit lower="0" upper="1.22" effort="1.5" velocity="3.59" />
    <dynamics damping="0.0209" friction="0.0300" />
  </joint>

</robot>
